[2023-08-03T21:26:29.621+0000] {taskinstance.py:1103} INFO - Dependencies all met for dep_context=non-requeueable deps ti=<TaskInstance: tiago_dag.my_task manual__2023-08-03T21:19:39.475221+00:00 [queued]>
[2023-08-03T21:26:29.637+0000] {taskinstance.py:1103} INFO - Dependencies all met for dep_context=requeueable deps ti=<TaskInstance: tiago_dag.my_task manual__2023-08-03T21:19:39.475221+00:00 [queued]>
[2023-08-03T21:26:29.637+0000] {taskinstance.py:1308} INFO - Starting attempt 4 of 6
[2023-08-03T21:26:29.666+0000] {taskinstance.py:1327} INFO - Executing <Task(BashOperator): my_task> on 2023-08-03 21:19:39.475221+00:00
[2023-08-03T21:26:29.676+0000] {standard_task_runner.py:57} INFO - Started process 362 to run task
[2023-08-03T21:26:29.681+0000] {standard_task_runner.py:84} INFO - Running: ['***', 'tasks', 'run', 'tiago_dag', 'my_task', 'manual__2023-08-03T21:19:39.475221+00:00', '--job-id', '94', '--raw', '--subdir', 'DAGS_FOLDER/second_dag.py', '--cfg-path', '/tmp/tmpqmf_zgp0']
[2023-08-03T21:26:29.687+0000] {standard_task_runner.py:85} INFO - Job 94: Subtask my_task
[2023-08-03T21:26:29.757+0000] {task_command.py:410} INFO - Running <TaskInstance: tiago_dag.my_task manual__2023-08-03T21:19:39.475221+00:00 [running]> on host 2917a9e5274d
[2023-08-03T21:26:29.901+0000] {taskinstance.py:1547} INFO - Exporting env vars: AIRFLOW_CTX_DAG_OWNER='***' AIRFLOW_CTX_DAG_ID='tiago_dag' AIRFLOW_CTX_TASK_ID='my_task' AIRFLOW_CTX_EXECUTION_DATE='2023-08-03T21:19:39.475221+00:00' AIRFLOW_CTX_TRY_NUMBER='4' AIRFLOW_CTX_DAG_RUN_ID='manual__2023-08-03T21:19:39.475221+00:00'
[2023-08-03T21:26:29.904+0000] {subprocess.py:63} INFO - Tmp dir root location: /tmp
[2023-08-03T21:26:29.905+0000] {subprocess.py:75} INFO - Running command: ['/bin/bash', '-c', 'touch dags/text.txt']
[2023-08-03T21:26:29.920+0000] {subprocess.py:86} INFO - Output:
[2023-08-03T21:26:29.924+0000] {subprocess.py:93} INFO - touch: cannot touch 'dags/text.txt': No such file or directory
[2023-08-03T21:26:29.924+0000] {subprocess.py:97} INFO - Command exited with return code 1
[2023-08-03T21:26:29.944+0000] {taskinstance.py:1824} ERROR - Task failed with exception
Traceback (most recent call last):
  File "/home/airflow/.local/lib/python3.7/site-packages/airflow/operators/bash.py", line 211, in execute
    f"Bash command failed. The command returned a non-zero exit code {result.exit_code}."
airflow.exceptions.AirflowException: Bash command failed. The command returned a non-zero exit code 1.
[2023-08-03T21:26:29.950+0000] {taskinstance.py:1350} INFO - Marking task as UP_FOR_RETRY. dag_id=tiago_dag, task_id=my_task, execution_date=20230803T211939, start_date=20230803T212629, end_date=20230803T212629
[2023-08-03T21:26:29.971+0000] {standard_task_runner.py:109} ERROR - Failed to execute job 94 for task my_task (Bash command failed. The command returned a non-zero exit code 1.; 362)
[2023-08-03T21:26:30.013+0000] {local_task_job_runner.py:225} INFO - Task exited with return code 1
[2023-08-03T21:26:30.043+0000] {taskinstance.py:2653} INFO - 0 downstream tasks scheduled from follow-on schedule check
